<mujoco model="Particle">
  <!-- <include file="../common.xml"/> -->

  <!-- <option timestep="0.01"> -->
    <!-- <flag contact="disable"/> -->
  <!-- </option> -->

  <!-- <default>
    <joint type="hinge" axis="0 0 1" limited="true" range="-.29 .29" damping="1"/>
    <motor gear=".1" ctrlrange="-1 1" ctrllimited="true"/>
  </default> -->

  <worldbody>
    <light name="light" pos="0 0 1"/>
    <camera name="fixed" pos="0 0 .75" quat="1 0 0 0"/>
    <geom name="ground" type="plane" pos="0 0 0" size="2 2 .1" material="blue_grid"/>
    <!-- <geom name="wall_x" type="plane" pos="-.3 0 .02" zaxis="1 0 0"  size=".02 .3 .02" material="decoration"/>
    <geom name="wall_y" type="plane" pos="0 -.3 .02" zaxis="0 1 0"  size=".3 .02 .02" material="decoration"/>
    <geom name="wall_neg_x" type="plane" pos=".3 0 .02" zaxis="-1 0 0"  size=".02 .3 .02" material="decoration"/>
    <geom name="wall_neg_y" type="plane" pos="0 .3 .02" zaxis="0 -1 0"  size=".3 .02 .02" material="decoration"/> -->



    <body name="object" pos="0.25 0 0.02" quat="1 0 0 0">
        <geom type="box" size="0.01 0.03 0.02" rgba="0 1 0 .5"/>
        <joint name="object_jnt" type="free"/>
    </body>

    <body name="pointmass" pos="0.23 0 .001" gravcomp="1">
      <camera name="cam0" pos="0 -0.3 0.3" xyaxes="1 0 0 0 0.7 0.7"/>
      <joint name="root_x" type="slide"  pos="0 0 0" axis="1 0 0" />
      <joint name="root_y" type="slide"  pos="0 0 0" axis="0 1 0" />
      <joint name="root_z" type="slide"  pos="0 0 0" axis="0 0 1" />
      <geom name="pointmass" type="sphere" size=".001" mass="0.05"/>
      <site name="tip" pos="0 0 0" size="0.001"/>
    </body>
  </worldbody>

  <actuator>
    <velocity name="x_vel" joint="root_x" kv="10" ctrllimited="true" ctrlrange="-0.05 0.05"/>
    <velocity name="y_vel" joint="root_y" kv="10" ctrllimited="true" ctrlrange="-0.05 0.05"/>
    <velocity name="z_vel" joint="root_z" kv="10" ctrllimited="true" ctrlrange="-0.05 0.05"/>
    <!-- <motor name="x_vel" joint="root_x" gear="1" ctrllimited="true" ctrlrange="-1 1"/>
    <motor name="y_vel" joint="root_y" gear="1" ctrllimited="true" ctrlrange="-1 1"/>
    <motor name="z_vel" joint="root_z" gear="1" ctrllimited="true" ctrlrange="-1 1"/> -->

  </actuator>
</mujoco>
